## `error`

`error` 是 Go 中用于处理常规错误的机制，通过函数返回值传递错误，调用方负责检查并处理。

### 核心特性补充

1. **高效的错误传递机制**  
   `error` 值是轻量的，传递效率高，不会显著增加运行时开销。

2. **链式错误封装**  
   利用 `fmt.Errorf` 或 `errors.Join`，可以将多个错误组合起来，或在传递时添加上下文信息。

### 使用示例优化

#### 创建和返回错误

推荐的现代方式是通过 `fmt.Errorf` 添加上下文信息，而不是直接创建简单错误。

```go
package main

import (
	"errors"
	"fmt"
)

func doSomething() error {
	return fmt.Errorf("operation failed: %w", errors.New("something went wrong"))
}

func main() {
	err := doSomething()
	if err != nil {
		fmt.Println("Error:", err)
	}
}
```

#### 链式错误组合（Go 1.20+）

`errors.Join` 可以将多个错误组合成一个。

```go
package main

import (
	"errors"
	"fmt"
)

func main() {
	err1 := errors.New("file not found")
	err2 := errors.New("network timeout")
	combinedErr := errors.Join(err1, err2)
	fmt.Println("Combined Error:", combinedErr)
}
```

#### 错误检测（解包）

Go 提供 `errors.Is` 和 `errors.As` 检测具体错误。

```go
package main

import (
	"errors"
	"fmt"
)

var ErrNotFound = errors.New("not found")

func doSomething() error {
	return fmt.Errorf("operation failed: %w", ErrNotFound)
}

func main() {
	err := doSomething()
	if errors.Is(err, ErrNotFound) {
		fmt.Println("Specific error detected: not found")
	}
}
```

#### 自定义错误类型（推荐结构体）

将上下文信息封装到自定义错误类型中。

```go
package main

import (
	"fmt"
)

type MyError struct {
	Op  string
	Err error
}

func (e MyError) Error() string {
	return fmt.Sprintf("operation %s failed: %v", e.Op, e.Err)
}

func doSomething() error {
	return MyError{Op: "database connect", Err: fmt.Errorf("timeout")}
}

func main() {
	err := doSomething()
	fmt.Println("Error:", err)
}
```

---

## `panic` 和 `recover`

`panic` 是处理程序不可恢复错误的工具，适用于异常情况或严重错误。结合 `recover`，可以有效控制程序流。

### 核心特性补充

1. **非预期行为**：`panic` 应只用于真正的异常场景（如程序逻辑错误），不应作为普通错误处理工具。
2. **清理资源**：在引发 `panic` 后，Go 会先运行 `defer` 的代码块，用于清理资源。
3. **中断级联**：`panic` 会向调用栈传播，直到触发 `recover` 或程序退出。

### 使用建议

1. 避免滥用 `panic`，可控的错误应优先使用 `error`。
2. 始终使用 `recover` 结合 `defer`，确保资源释放和问题排查。

### 使用示例优化

#### 捕获并恢复 `panic`

用 `recover` 捕获并记录错误，同时让程序继续运行。

```go
package main

import "fmt"

func safeDivision(a, b int) (result int) {
	defer func() {
		if r := recover(); r != nil {
			fmt.Println("Recovered from panic:", r)
			result = 0 // 设置默认值
		}
	}()
	return a / b
}

func main() {
	fmt.Println("Result:", safeDivision(10, 2)) // 正常执行
	fmt.Println("Result:", safeDivision(10, 0)) // 捕获 panic
}
```

#### 资源清理

结合 `defer` 和 `recover`，确保资源在异常情况下也能正确释放。

```go
package main

import (
	"fmt"
	"os"
)

func writeFile(filename string, data string) {
	file, err := os.Create(filename)
	if err != nil {
		panic(fmt.Sprintf("failed to create file: %v", err))
	}
	defer func() {
		if r := recover(); r != nil {
			fmt.Println("Recovered from panic:", r)
		}
		file.Close()
	}()
	_, err = file.WriteString(data)
	if err != nil {
		panic(fmt.Sprintf("failed to write data: %v", err))
	}
}

func main() {
	writeFile("example.txt", "Hello, Go!")
	fmt.Println("File written successfully")
}
```

#### 多层 `panic` 捕获

`panic` 会向调用栈层层传播，直到有 `recover` 捕获。

```go
package main

import "fmt"

func level1() {
	defer func() {
		if r := recover(); r != nil {
			fmt.Println("Recovered at level1:", r)
		}
	}()
	level2()
}

func level2() {
	defer func() {
		if r := recover(); r != nil {
			fmt.Println("Recovered at level2:", r)
			panic(r) // 再次抛出，让上层处理
		}
	}()
	panic("something went terribly wrong")
}

func main() {
	level1()
	fmt.Println("Program continues")
}
```

---

## `error` 和 `panic` 的对比

| 特性             | `error`                       | `panic`                         |
|------------------|-------------------------------|----------------------------------|
| **用途**         | 处理可预期的错误              | 处理不可恢复的严重错误           |
| **表现形式**     | 返回值传递                    | 直接中断程序执行                 |
| **处理方式**     | 调用方检查并处理              | 通过 `recover` 捕获，恢复程序流 |
| **使用场景**     | 文件不存在、网络超时等普通错误 | 数组越界、未捕获的异常等致命错误 |
